Workbook
Name Alist: 'A. Completeness'!$K$2:$K$4
Name Blist: 'A. Completeness'!$K$3:$K$4
Name CHIP: 'Cover Sheet'!$J$2:$J$7
Name Clist: 'A. Completeness'!$K$1
Name Ilist: 'B. Enrollment & Disenrollment'!$L$2:$L$3
Name Medicaid: 'Cover Sheet'!$J$2:$J$7
Name MMC: 'Cover Sheet'!$J$2:$J$8
Name MUNN: 'A. Completeness'!$J$1:$J$4
Name Rlist: 'B. Enrollment & Disenrollment'!$M$2:$M$3
Name YNNN: 'A. Completeness'!$L$1:$L$4
Name OLE_LINK1: Instructions!$B$6
Name Ilist: 'A. Completeness'!$L$2:$L$3
Name Rlist: 'A. Completeness'!$M$2:$M$3
Name Ilist: 'C. Beneficiary Notification'!$L$2:$L$3
Name Rlist: 'C. Beneficiary Notification'!$M$2:$M$3
Name Ilist: 'D. Payment'!$L$2:$L$3
Name Rlist: 'D. Payment'!$M$2:$M$3
Name Ilist: 'E. Providers & Network'!$L$2:$L$3
Name Rlist: 'E. Providers & Network'!$M$2:$M$3
Name Ilist: 'F. Coverage'!$L$2:$L$3
Name Rlist: 'F. Coverage'!$M$2:$M$3
Name Ilist: 'G. Quality and UM'!$L$2:$L$3
Name Rlist: 'G. Quality and UM'!$M$2:$M$3
Name Ilist: 'H. Grievances and Appeals'!$L$2:$L$3
Name Rlist: 'H. Grievances and Appeals'!$M$2:$M$3
Name Ilist: 'I. Program Integrity'!$L$2:$L$3
Name Rlist: 'I. Program Integrity'!$M$2:$M$3
Name Ilist: 'J. General Terms and Conditions'!$L$2:$L$3
Name Rlist: 'J. General Terms and Conditions'!$M$2:$M$3
Name Ilist: 'K. Health Information Systems'!$L$2:$L$3
Name Rlist: 'K. Health Information Systems'!$M$2:$M$3

Sheet Table of Contents
A1: Table of Contents
A2: Instructions
A3: Cover Sheet
A4: Contract Completeness
A5: I.A.1 Contract Completeness
A6: Enrollment and Disenrollment
A7: I.B.1 No Discrimination
A8: I.B.2 Choice of Doctor
A9: I.B.3 Opt-Out
A10: I.B.4 Reenrollment
A11: I.B.5 Disenrollment
A12: I.B.6 Disenrollment Request Process
... A100: Glossary

Sheet Instructions
A1: Instructions
A2: Note to Analysts | B2: Regulations at 42 Code of Federal Regulations (CFR) 438.3(a) specify that the Centers for Medicare & Medicaid Services (CMS) must review and approve all managed care organization (MCO), prepaid inpatient health plan (PIHP), and prepaid ambulatory health plan (PAHP) contracts, including those risk and non-risk contracts that, on the basis of their value (less than $1,000,000) are not subject to prior approval requirements in 42 CFR 438.806. 42 CFR 438.3(r) requires CMS review and approval of primary care case management (PCCM) entity contracts for provisions related to 42 CFR 438.3(q), 42 CFR 438.10 and 42 CFR 438.310(c)(2). The CMS Contract Checklist is intended for use by Division of Managed Care Operations (DMCO) staff in evaluating state Medicaid managed care contracts. The checklist contains references and contract requirements collected from the CFR, State Medicaid Director (SMD) letters, the Social Security Act (the Act), the American Reinvestment and Recovery Act of 2009 (ARRA), and the Patient Protection and Affordable Care Act (ACA). The citations are arranged in order of precedence, with the statutory cite being primary.
A3: Getting Started | B3: Complete the cover sheet in its entirety before moving on to the other tabs. If prompted in the Excel header, please select “enable editing” or “enable content” to enable the functionality in this workbook.
A4: Reminder | B4: NEVER copy and paste information from one cell into another cell. This will cause issues with functionality and create errors.
A5: Cover Sheet
A6: About this Review | B6: Based on the information the analyst enters on the cover sheet, the Excel spreadsheet will shade out requirements that are not applicable to the contract action. Please follow the instructions in the cover sheet to fill in all applicable information.
B7: Does the contract cover Medicaid or both Medicaid and CHIP? (cell B4). Please select "Medicaid" if the managed care contract covers only Medicaid enrollees, including Medicaid expansion CHIP (Title XIX) enrollees. Select "Both" if the contract covers both Medicaid and separate CHIP enrollees.
B8: Type of Review (cell B6). Select either base contract or contract amendment.
B9: Start Date of Review (cell B7). The date of review must be entered for every review.
B10: Medicaid Federal Operating Authority(ies) (cell B10). Choose all options that apply: 1915(a)(1)(A) voluntary, State Plan Amendment (Title XIX), 1915(b) waiver, 1115 waiver, and/or Other.
B11: Type of Entity (cell B13-B18). Select the appropriate entity type(s): MCO, health insuring organization (HIO), PIHP, PAHP, non-emergency medical transportation (NEMT) PAHP, or PCCM entity. When an analyst selects an entity type, the tool will shade out any items that do not apply to that entity type. For example, if the analyst selects PIHP, the tool will shade out any requirements that do not apply to PIHPs. Note: 42 CFR Part 438 does not require CMS review and approval of PCCM managed care contracts.
B12: Is the entity risk-bearing or non-risk bearing? (cell B19). MCOs are always risk bearing in accordance with 42 CFR 438.2 and 42 CFR 457.10; however, for non-risk bearing entities, the managed care plan (MCP) is not at financial risk for changes in utilization or for costs that do not exceed the upper payment limits. Therefore, PIHPs, PAHPs, and NEMT PAHPs may be risk-based or non-risk-based. Note: This field must be completed in every review for the base and amendment start and end date features to function correctly.
B13: Base Contract Period Start and End Dates (cells B21 and B22). The base contract start and end dates must be entered in every review (including reviews of contract amendments). If the contract action implements a contract extension, the base contract end date entered should be the date on which the extension period ends.
B14: Amendment Start and End Dates (cells B23 and B24). The amendment start and end dates must be entered in every review of a contract amendment(s) to determine whether requirements effective after a certain date should be evaluated or shaded out. If the contract amendment implements a contract extension, the amendment end date should be the date on which the extension period ends. If the contract amendment has no end date, the amendment end date entered should be the date on which the base contract ends.
B15: Rating Period Start and End Dates (cells B25 and B26). A rating period start date and rating period end date must be entered for all risk-based Medicaid managed care contract reviews to determine whether requirements that phase in after a certain date should be evaluated or shaded out. For contract actions that do not implement rates, the rating period start and end dates should reflect the annual rating period during which the start date of the contract action falls. Example: If a state uses a July–June annual rating period and executes a contract action to modify access requirements effective 10/01/17, a rating period start date of 07/01/17 and a rating period end date of 06/30/18 should be entered. For non-risk based contracts, enter "N/A" in this field.
B16: Is this an entirely new managed care program? (cell B27). For new managed care programs, a comprehensive review of the contract must be completed. If it is not a new managed care program and a comprehensive review has been completed within the past five years, a streamlined review may be completed.
B17: Has it been more than five years since the last comprehensive review? (cell B28). For contracts that have not had a comprehensive review within the past five years, a comprehensive review must be completed. If a comprehensive review has been completed within the past five years and it is not a new managed care program, a streamlined review may be completed.
B18: Comprehensive Review or Streamlined Review? (cell B29). Denotes whether the review will be a comprehensive or streamlined review.
A19: Status of Review by Section Dashboard | B19: (Cells B29-C41): This section indicates the status of the Medicaid requirements in each tab of the checklist. This section is intended to help the analyst completing this checklist review which tabs they have completed, and which tabs remain to be completed. The status section is intended primarily to support the review of entire contracts. If the analyst is completing a review of an amendment, only the provisions pertaining to the amendment should be completed. The Medicaid requirements status is populated based on the analyst’s progress through tab A–K of the checklist. The "Decision" fields in tabs A–K (columns G and H in the upper right-hand corner of each tab) determine the statuses that appear in the Status of Review by Section Dashboard. Status options include: "Not started", "Revisions needed", "Section review N/A", or "Approved". Note that entire sections of the checklist may be “N/A.”
A20: Tabs A–K
A21: Status Indicators
A22: Status of Medicaid Section | B22: A group of cells in the upper right-hand corner of sections A–K of the checklist display an analyst's progress through each tab, and its outcome (i.e., “decision”). Status of Medicaid Section: The "Status of Section" fields indicate an analyst’s progress through the Medicaid requirements within the tab. This tab will display one of the following values: “Not Started”, “In Progress”, “Section Review Complete”, or “Section Review N/A”. In most cases, when at least one field in column E contains a valid value, the "Status of Section Review" will change from “Not Started” to “In Progress." Completing tabs A–K. The “Status of Section” indicator will display “Section Review Complete” when all requirements in the section are: (1) Marked as “Met” with appropriate documentation provided within the “Where Found” cell; (2) Marked as “N/A” with appropriate documentation provided within the “General Comments” cell; documentation should describe why a given requirement is not applicable to the managed care contract; (3) Marked as "Unsure" with information provided in the "Follow-up Required" cell; or (4) Marked as "Not met" with information provided in the "Follow-up Required" cell. In tab A (Completeness), options of "Yes", "No", and "No, submission is in draft" are also available. (5) For "Yes", information must be provided in the "Where found" cell. (6) For "No" and "No, submission is in draft", information must be provided in the "Follow-up Required" cell.
A23: Status of Medicaid Decision | B23: Medicaid Decision. While a section is “In Progress” or “Not Started,” the “Medicaid Decision" fields will mirror the Status of Medicaid Review. Once the review is complete (meaning a status and any required detail has been entered for every requirement, as described in Status Indicators: (1) Status of Medicaid Section), the “Medicaid Decision" fields will display one of the following statuses: (1) “Approved” if all of the status fields are: (a) Marked "Met" or "Yes" with appropriate documentation provided within the “Where Found” cell; or (b) Marked as “N/A” with appropriate documentation provided within the “General Comments” cell; documentation should describe why a given requirement is not applicable to the managed care contract. (2) “Revisions needed,” if the status fields contain at least one instance of a requirement that is "Not met" or "Unsure."
A24: Column Descriptions
A25: (A) Item | B25: Item number aligns with the numbering in the State Guide to CMS Requirements for Medicaid Managed Care Contract Review and Approval.
A26: (B) Legal Cite | B26: Statutory and regulatory citations that further clarify the requirement are listed in this column. Other citations, such as SMD letters, are listed below the statutory and regulatory references so that an evaluator may refer to other resources for further clarification.
A27: (C) Requirement | B27: Includes the statutory and/or regulatory language for each legal citation.
A28: (D) Tip | B28: Some items have tips that provide more information about the requirement.
A29: (E) Status | B29: Choices include "Met", "Not met", "Unsure", or "N/A" for each requirement. If the row is shaded out, the requirement does not apply and the analyst will be unable to select a status. A section of the checklist will not be listed as “Complete” unless each requirement within that section is either: (1) marked as “Met” with appropriate documentation provided within the “Where Found” cell; (2) marked as “N/A” with appropriate documentation provided within the “General Comments” cell describing why a given requirement is not applicable to the managed care contract; (3) marked as "Unsure" with information provided in the "Follow-up Required" cell; or (4) marked as "Not met" with information provided in the "Follow-up Required" cell. In tab A (Completeness), options of "Yes", "No", and "No, submission is in draft" are also available. For "Yes", information must be provided in the "Where Found" cell. For "No" and "No, submission is in draft", information must be provided in the "Follow-up Required" cell. In some circumstances, information in the cover sheet will allow analysts to mark entire sections as “N/A.” For example, this option appears when the section requirements do not apply to the “Type of Entity." Analysts must verify whether any items in the section are applicable before selecting “N/A” for a given section.
A30: (F) Where Found | B30: Analysts may use this column to fill in the contract section and page number (or other citation) that indicates or provides documentation that the requirement has been met. Page numbers can change between different versions of the same contract, so using section references is preferred. This documentation is required for a given federal requirement to be appropriately considered “Met.”
A31: (G) Follow-up Required | B31: Analysts may use this column to include notes on any follow-up actions needed to bring a requirement from "Unsure" or "Not met" to "Met." If a given requirement is listed as "Not met" or "Unsure", the analyst must provide information in this column.
A32: (H) General Comments | B32: Analysts may use this column to record any additional notes that have not been captured elsewhere. If a given requirement is listed as “N/A", the analyst must use this column to document the rationale for indicating that the requirement is not applicable.
A33: (C:3) Marking an Entire Tab as "N/A" | B33: Tabs B–K have a field in A3 that reads: “Mark all requirements as “N/A?” There are two potential corresponding values in cell C3: (1) “No, section requirements must be reviewed” or (2) “yes, section requirements are not applicable.” Note that option (1) “No, section requirements must be reviewed” is the default value and option (2) “yes, section requirements are not applicable” must be selected in order to mark the entire tab as "N/A."
A34: General Guidance for Using the Checklist
A35: Model Contracts | B35: If the state uses a model contract with multiple contractors, the lead analyst may complete a single review tool. However, if the start dates differ amongst contractors, analysts should complete a separate review tool for each start date to ensure all newly effective requirements are captured in the review.
A36: Summary of Review | B36: Run the summary by following the instructions at the top of the page. The summary provides a list of all "Unsure" and "Unmet" provisions. These items should be followed up on immediately with the state and monitored for additional follow-up action as needed.
A37: Guidance for Evaluating Contracts | B37: In each applicable tab A–K, analysts should evaluate the contract language and compare it to the “Requirement” column (C) in the table to determine whether the required language is contained in the contract. Column “Where Found” (F) is provided for the analyst's use in noting where the required language is found in the contract or other document. If the language is present and fulfills the requirement, analysts should use the drop-down “Status” menus (Column E) to select "Met" in the appropriate row. If the language is absent, evaluators should select "Not met" or indicate that they are "Unsure" and enter information in the "Follow-up Required” column (G). Resolution of issues concerning absent or incomplete requirements is left up to the discretion of the evaluation team. Note: Because the statements referred to in this checklist are federal requirements, it is not sufficient to have generic contract language saying the contractor must comply with all federal statutes and regulations. Where any discrepancies exist between an SMD or State Health Official (SHO) letter and the Medicaid/CHIP managed care regulations, regulations supersede the SMD and SHO letter. All items in this checklist are applicable to the designated entity types regardless of the operating authority in effect unless the requirement is specifically waived in the authorizing documents, including the state plan or a waiver.
A38: Tips & Comment Flags | B38: Within each tab of the checklist, some items may have tips that provide more information about a requirement. Tips should be reviewed by the analyst when evaluating a particular item. Tips are noted with a numeric citation in column D and are linked to the corresponding tip at the bottom of the tab. If a cell contains a comment flag, it will be indicated by a red triangle in the upper right hand corner of a given cell. Content for comment flags will display when a user hovers the mouse over the cell. To view all comments, a user can right-click on the tab and select "Show/Hide Comments."
A39: Changing Cell Size to Show Text | B39: Column widths are fixed. However, analysts may modify row heights to show any hidden text in a cell or to show text that analysts have entered in the checklist.
A40: Glossary | B40: A glossary tab provides definitions of commonly used terms and acronyms.

Sheet Cover Sheet
A1: CMS Review Tool for Medicaid Managed Care Contract Approval | F1: Values for Form Fields - Do not modify | M1: Headers for B15:18 | N1: =IF($B$19="Non-risk","(Placeholder)",IF($B$19="Risk","Rating Period Start Date","(Type of Review not selected)")) | O1: Headers for A21:A22
F2: Base contract | G2: state | H2: 1915(a)(1)(A) voluntary | I2: Draft | J2: MCO | K2: Approved | L2: Risk | M2: =IF($B$6="Base contract","Base Contract Effective Date (Required, if not crosshatched)",IF($B$6="Streamlined","Base Contract Effective Date (Required, if not crosshatched)",IF($B$6="Contract amendment","Base Contract Effective Date (Required, if not crosshatched)","(Type of Review not selected) (Required, if not crosshatched)"))) | N2: =IF($B$19="Non-risk","(Placeholder)",IF($B$19="Risk","Rating Period End Date","(Type of Review not selected)")) | O2: =IF($B$4="Both", "(Placeholder)", "Rating Period Start Date (Required, if not crosshatched)")
A3: About this Review | B3: Complete the boxes below. Select from drop-down menu where applicable | C3: Analyst Notes | D3: Description/Instructions | F3: Contract amendment | G3: Alabama | H3: State Plan Amendment (Title XIX) | I3: Executed | J3: HIO | K3: Revisions needed | L3: Non-risk | M3: =IF($B$6="Base contract","Base Contract End Date (Required, if not crosshatched)",IF($B$6="Streamlined","Base Contract End Date (Required, if not crosshatched)",IF(OR($B$6="Contract amendment","Streamlined"),"Base Contract End Date (Required, if not crosshatched)","(Type of Review not selected) (Required, if not crosshatched)"))) | O3: =IF($B$4="Both", "(Placeholder)", "Rating Period End Date (Required, if not crosshatched)")
A4: Does the contract cover Medicaid or both Medicaid and CHIP? (Required) | B4: Both | D4: Select “Medicaid” if the managed care contract covers only Medicaid enrollees, including Medicaid expansion CHIP (Title XIX) enrollees. Select “Both” if the contract covers both Medicaid and separate CHIP enrollees. | G4: Alaska | H4: 1115 waiver | J4: PIHP | M4: =IF($B$6="Base contract","(Placeholder)",IF($B$6="Contract amendment","Contract Amendment Effective Date (Required, if not crosshatched)",IF($B$6="Streamlined","Contract Amendment Effective Date (Required, if not crosshatched)","(Type of Review not selected) (Required, if not crosshatched)")))
A5: Reviewer | D5: Enter each reviewer's first and last name. | G5: Arizona | H5: 1915(b) waiver | J5: PAHP | M5: =IF($B$6="Base contract","(Placeholder)",IF($B$6="Contract amendment","Contract Amendment End Date (Required, if not crosshatched)",IF($B$6="Streamlined","Contract Amendment End Date (Required, if not crosshatched)","(Type of Review not selected) (Required, if not crosshatched)")))
A6: Type of Review (Required) | D6: A base contract is the state's full contract with an MCP; a contract amendment changes an existing base contract. | G6: Arkansas | H6: Other | J6: NEMT PAHP
A7: Start Date of Review (Required if not crosshatched) | D7: Enter date in 00/00/0000 format. | G7: California | H7: State Plan Amendment (Title XXI) | J7: PCCME
A8: State | D8: Select name of state. | G8: Colorado | H8: 1115 waiver | M8: =IF(OR($B$4="Both"),"Both","Medicaid")
A9: Name of Program(s) | D9: Enter the name of the program(s) included in this contract. | G9: Connecticut | J9: Yes
A10: Medicaid Federal Operating Authority (select all that apply) | D10: Select the Medicaid federal operating authority. | G10: Delaware | J10: No
A11: Contract Start Date | D11: The date on which the full contract began/will begin. If the contract being submitted for review is an amendment to an existing contract, the start date is the date on which the amendment will/did go into effect. | G11: Dist. of Col.
A12: Name of Model Contract/Name of MCP | D12: Enter "model contract" if the state uses this same contract language for more than one MCP contract. If the contract language is unique, enter the name of the MCP. | G12: Florida
A13: Does the contract apply to an MCO? | B13: Yes | D13: An MCP that has, or is seeking to qualify for, a comprehensive risk contract. | G13: Georgia
A14: Does the contract apply to an HIO? | D14: With the exception of California, please select “No” under the drop-down menu. A county operated MCP that, in exchange for capitation payments, covers services for beneficiaries. | G14: Hawaii
A15: Does the contract apply to a PIHP? | D15: An MCP that provides inpatient hospital or institutional services, does not have a comprehensive risk contract, and receives capitation payments or other payment arrangements that do not use state plan rates. | G15: Idaho
A16: Does the contract apply to a PAHP? | D16: An MCP that provides services, but is not responsible for inpatient hospital or institutional services and receives capitation payments, or other payment arrangements that do not use state plan rates. | G16: Illinois
A17: Does the contract apply to a NEMT PAHP? | D17: An MCP that provides only NEMT services to enrollees, and receives capitation payments, or other payment arrangements that do not use state plan rates. | G17: Indiana
A18: Does the contract apply to a PCCM Entity? | D18: An MCP that provides services as defined in regulation in addition to PCCM services for the state. | G18: Iowa | M18: Yes
A19: Is MCP risk-bearing or non-risk bearing? (Required) | D19: MCOs are always risk bearing in accordance with 42 CFR 438.2 and 42 CFR 457.10. PIHPs, PAHPs, and NEMT PAHPs may be risk-based or non-risk-based. This does not need to be completed for PCCM-entity. | G19: Kansas | M19: No
A20: Type of Contract (Required) | D20: Is the contract in draft form or has it been executed? | G20: Kentucky
A21: =M2 | D21: The date on which the base contract begins. | G21: Louisiana | M21: Comprehensive Review
A22: =M3 | D22: The date on which the base contract ends. | G22: Maine | M22: Streamlined Review
A23: =M4 | D23: The date on which the contract amendment begins. | G23: Maryland
A24: =M5 | D24: The date on which the contract amendment ends. | G24: Massachusetts
A25: Rating Period Start Date | D25: The date on which the associated contract rating period begins. For contract actions that do not implement rates, the rating period start and end dates should reflect the annual rating period during which the start date of the contract action falls. | G25: Michigan
A26: Rating Period End Date | D26: The date on which the associated contract rating period ends. | G26: Minnesota
A27: Is this an entirely new managed care program? (Required) | D27: Comprehensive review is required for new managed care programs. | G27: Mississippi
A28: Has it been more than five years since the last comprehensive review was completed? (Required) | D28: Comprehensive review is required for contracts that have not had a comprehensive review within the past five years. | G28: Missouri
A29: Comprehensive Review or Streamlined Review? (Required) | D29: Denotes whether the review will be a comprehensive or streamlined review. | G29: Montana
G30: Nebraska
A31: Status of Review by Section Dashboard | B31: Medicaid Requirements | C31: (Please provide additional comments) | G31: Nevada
B32: (Status/Decision fields below will update automatically) | G32: Ohio
A33: A. Completeness | B33: ='A. Completeness'!$H$3 | G33: Oklahoma
A34: B. Enrollment and Disenrollment | B34: ='B. Enrollment & Disenrollment'!H3 | G34: Oregon
A35: C. Beneficiary Notification | B35: ='C. Beneficiary Notification'!$H$3 | G35: Pennsylvania
A36: D. Payment | B36: ='D. Payment'!$H$3 | G36: Puerto Rico
A37: E. Providers and Provider Networks | B37: ='E. Providers & Network'!H3 | G37: New Hampshire
A38: F. Coverage | B38: ='F. Coverage'!H3 | G38: New Jersey
A39: G. Quality and Utilization Management (UM) | B39: ='G. Quality and UM'!H3 | G39: New Mexico
A40: H. Grievances and Appeals | B40: ='H. Grievances and Appeals'!H3 | G40: New York
...

Sheet A. Completeness
A1: Subpart A - Contract Completeness | J1: Met | L1: Yes | M1: =IF($C$2="Base contract","Blist",IF($C$2="Contract Amendment","Alist")) | V1: Risk v non-risk? | Z1: This contract applies to the following entity types | AH1: Contract/RP start dates NOT supplied in cover sheet? | AI1: Contract Period Start Date | AJ1: Rating Period Start Date | AK1: Review date NOT supplied in cover sheet | AL1: Review Date | AP1: Does the review include Medicaid and CHIP? | AV1: N/A
A2: Type of Review: | C2: ='Cover Sheet'!B6 | G2: Status of Medicaid Section: | H2: =I2 | I2: =IF(OR($C$3="Yes, section requirements are not applicable",$C$3="Yes, all requirements on the sheet are crosshatched"),"Section Review N/A",IF((COUNTA(A9:A32)+COUNTBLANK(A9:A32)=COUNTBLANK(E9:E32)),"Not Started",IF((COUNTA(A9:A32)>SUM(U9:U32)),"In Progress","Section Review Complete"))) | J2: Unsure | K2: Yes, section requirements are not applicable | L2: No | V2: ='Cover Sheet'!B19 | Z2: =IF('Cover Sheet'!$B$13="Yes","MCO","--") | AA2: =IF('Cover Sheet'!$B$14="Yes","HIO","--") | AB2: =IF('Cover Sheet'!$B$15="Yes","PIHP","--") | AC2: =IF('Cover Sheet'!$B$16="Yes","PAHP","--") | AD2: =IF('Cover Sheet'!$B$17="Yes","NEMT PAHP","--") | AE2: =IF('Cover Sheet'!$B$18="Yes","PCCME","--") | AK2: =IF('Cover Sheet'!$B$7="",TRUE,FALSE) | AL2: =IF($AK$2=FALSE,'Cover Sheet'!$B$7,"") | AP2: =IF('Cover Sheet'!$B$4="BOTH",1,0)
A3: Mark all requirements as "N/A"? | C3: No, section requirements must be reviewed | G3: Medicaid Decision: | H3: =I3 | I3: =IF(OR($C$3="Yes, section requirements are not applicable",$C$3="Yes, all requirements on the sheet are crosshatched"),"Section Review N/A",IF((COUNTA(A9:A32)+COUNTBLANK(A9:A32))=COUNTBLANK(E9:E32),"Not Started",IF(OR(COUNTA(A9:A32)+COUNTBLANK(A9:A32)<>COUNTIF(E9:E32,"Yes")+COUNTIF(E9:E32,"Met")+COUNTIF(E9:E32,"N/A")+COUNTBLANK(E9:E32),COUNTA(A9:A32)<>SUM(U9:U32)),"Revisions Needed","Approved"))) | J3: Not met | K3: No, section requirements must be reviewed | L3: No, submission is in draft
J4: N/A | K4: Yes, all requirements on the sheet are crosshatched | L4: N/A
S5: _EFFECTIVE | AV5: Medicaid_Only
P6: Std type (EXISTING or NEW) | Q6: List | R6: NR Ind | AK6: (b4) Reasons to Crosshatch | AS6: For logic check only:
A7: Item | B7: Legal Cite | C7: Requirement | D7: Tip | E7: Status | F7: Where Found | G7: Follow-up Required | H7: General Comments | I7: MCO | J7: HIO | K7: PIHP | L7: PAHP | M7: NEMT PAHP | N7: PCCM | O7: PCCME | S7: Effective | T7: Contract start date (DATE) or rating period start date (RP)? | U7: Row Completed? (1 if status = Unsure; status = Met and column G <>blank; or status = Not Met and column I<>not blank; OR parallel medicaid requirement = Met) | V7: If risk, use RP effective date. If non-risk, use CY date. | W7: Entire section marked NA | X7: Shaded | Y7: Entity Not Applied | AF7: If CHIP linking and no information in rows with gray shading in columns E through H; code as complete. If rows with gray shading have information in one or more cells, the status of the row will be counted as if gray shading did not appear. (See Column Descriptions for more information) | AG7: (a) Crosshatch b/c entity type not applicable? (True=Yes,False=No) | AH7: (b1) Crosshatch b/c requirement not in effect? Default is DO NOT crosshatch; if values in the following columns = TRUE, apply crosshatching | AI7: (b2a) Reason Exists To Not Crosshatch? Will be TRUE if Missing Any dates. | AJ7: (b2b) Reason Exists To Crosshatch? | AK7: (b4a) ''DATE" - Effective Date of Req > Contract Period Start Date | AL7: (b4b) "RP" - Effective Date of Req > Rating Period Start Date | AM7: (b4d) TRUE - Non-Risk in cover sheet and indicator=1 | AN7: (b4c) Section I vs II | AO7: CHIP Requirement | AP7: Does the CHIP section have a corresponding Medicaid section (Yes=1) | AQ7: If yes, link the Medicaid section item: | AR7: If yes, link the Medicaid Requirement: | AS7: Is the text the exact same? | AT7: Shading code | AU7: section1_no_link | AV7: Medicaid_Only | AW7: Linked Medicaid Requirement Status | AX7: Linked Medicaid Requirement Where Found | AY7: Linked Medicaid Requirement Followup Required | AZ7: Linked Medicaid General Comments | BA7: Row Started (1 if row has been started) | BB7: Requirement Met | BC7: All Required Medicaid Cols Filled (1=True) | BD7: Contract start date (DATE) or rating period start date (RP)? | BE7: Streamlined | BF7: Rating Period
C8: I.A.1 Contract Completeness | Z8: MCO | AA8: HIO | AB8: PIHP | AC8: PAHP | AD8: NEMT PAHP | AE8: PCCME
A9: I.A.1.01 | B9: N/A | C9: The contract submission is signed and dated by all parties. | F9: Source: CN-680000-FP122: 24 | H9: Recommendation: MET Response: The contract explicitly states that it is not valid until signed and dated by both parties. This indicates that the requirement for the contract submission to be signed and dated by all parties is met. Evidence: - "**IN WITNESS THEREOF,** the Parties hereto have caused this five hundred twenty-seven (527) page Contract, which includes any referenced attachments, to be executed by their undersigned officials as duly authorized. This Contract is not valid until signed and dated by both Parties." [CN-680000-FP122: 24] | I9: MCO | J9: HIO | K9: PIHP | L9: PAHP | M9: NEMT PAHP | O9: PCCME | P9: EXISTING | Q9: =IF(OR(AND($C$2="Base contract",$C$3="No, section requirements must be reviewed",$AG9=FALSE, $AH9=FALSE),AND($C$2="Contract amendment",$C$3="No, section requirements must be reviewed",$AG9=FALSE,$AH9=FALSE)),"YNNN") | U9: =IF(OR($E$8="N/A",AND(E9="Yes",F9<>""),AND(E9="N/A",H9<>""),AND(E9="Met",F9<>""),AND(E9="Not met",G9<>""),AND(E9="Unsure",G9<>""),AND(E9="N/A"),AND(E9="No",G9<>""),AND(E9="No, submission is in draft",G9<>""),AND(R9=1),AND(Y9=TRUE)),1,0) | W9: =IF($C$3="Yes, section is not applicable","TRUE","FALSE") | X9: =IF(OR(Y9=TRUE),TRUE,FALSE) | Y9: =IF(SUM(Z9:AE9)<1,TRUE,FALSE) | Z9: =IF($Z$2=I9,1,0) | AA9: =IF($AA$2=J9,1,0) | AB9: =IF($AB$2=K9,1,0) | AC9: =IF($AC$2=L9,1,0) | AD9: =IF($AD$2=M9,1,0) | AE9: =IF($AE$2=O9,1,0) | AM9: =IF(AND('Cover Sheet'!$B$19="Non-Risk",$R9=1),TRUE,FALSE) | AN9: =IF(AND($H$6="Medicaid",MID($A9,1,FIND(".",$A9,1)-1)="II"),TRUE,FALSE) | AV9: =IF(AU9=1,1,"") | BE9: 0
A10: I.A.1.02 | B10: N/A | C10: The contract submission is complete, meaning: • All pages, appendices, attachments, etc. were submitted to CMS. • Any documents incorporated by reference (including, but not limited to, state statute, state regulation, or other binding document, such as a member handbook) to comply with federal regulations and the requirements of this review tool were submitted to CMS. | F10: Source: CN-680000-FP122: 23, 24 | Attachment - Core Contract Provisions 02012025: 242 | CN-680000-FP122: 302, 467, 72, 539 | H10: Recommendation: UNCLEAR Response: The retrieved text does not provide explicit evidence that all pages, appendices, attachments, and documents incorporated by reference were submitted to CMS. While the contract mentions that it includes all terms and conditions agreed upon by the Parties and references attachments, it does not confirm that these were submitted to CMS. Additionally, there is no explicit mention of documents incorporated by reference being submitted. Evidence: - "This Contract and its attachments as referenced herein contain all the terms and conditions agreed upon by the Parties." [CN-680000-FP122: 23] - "List of Attachments included as part of this Contract:" [CN-680000-FP122: 24] - "**IN WITNESS THEREOF,** the Parties hereto have caused this five hundred twenty-seven (527) page Contract, which includes any referenced attachments, to be executed by their undersigned officials as duly authorized. This Contract is not valid until signed and dated by both Parties." [CN-680000-FP122: 24] | I10: MCO | J10: HIO | K10: PIHP | L10: PAHP | M10: NEMT PAHP | O10: PCCME | P10: EXISTING | Q10: =IF(OR(AND($C$2="Base contract",$C$3="No, section requirements must be reviewed",$AG10=FALSE, $AH10=FALSE),AND($C$2="Contract amendment",$C$3="No, section requirements must be reviewed",$AG10=FALSE,$AH10=FALSE)),"YNNN") | U10: =IF(OR($E$8="N/A",AND(E10="Yes",F10<>""),AND(E10="N/A",H10<>""),AND(E10="Met",F10<>""),AND(E10="Not met",G10<>""),AND(E10="Unsure",G10<>""),AND(E10="N/A"),AND(E10="No",G10<>""),AND(E10="No, submission is in draft",G10<>""),AND(R10=1),AND(Y10=TRUE)),1,0) | X10: =IF(OR(Y10=TRUE),TRUE,FALSE) | Y10: =IF(SUM(Z10:AE10)<1,TRUE,FALSE) | Z10: =IF($Z$2=I10,1,0) | AA10: =IF($AA$2=J10,1,0) | AB10: =IF($AB$2=K10,1,0) | AC10: =IF($AC$2=L10,1,0) | AD10: =IF($AD$2=M10,1,0) | AE10: =IF($AE$2=O10,1,0) | AM10: =IF(AND('Cover Sheet'!$B$19="Non-Risk",$R10=1),TRUE,FALSE) | AN10: =IF(AND($H$6="Medicaid",MID($A10,1,FIND(".",$A10,1)-1)="II"),TRUE,FALSE) | AV10: =IF(AU10=1,1,"") | BE10: 0
A11: N/A | B11: N/A | C11: If the contract submission is an amendment, CMS has approved the base contract, and all previous amendments have been approved that are related to or modifying the same provision(s), or are assumed to be implemented. | D11: 1 | F11: Source: CN-680000-FP122: 236, 236, 286 | Attachment - Core Contract Provisions 02012025: 175, 175, 217, 226 | H11: Recommendation: UNCLEAR Response: The retrieved text mentions that the Agency may amend and use CMS-approved rates and that any amendment to the contract must be in writing. However, there is no explicit statement that CMS has approved the base contract and all previous amendments related to or modifying the same provision(s). Therefore, it is unclear whether the requirement is met. Evidence: - 'he Agency may amend and use the CMS-approved rates by notice to the Managed Care Plan through an amendment to this Contract.' [CN-680000-FP122: 236] - 'The Agency may use, or may amend and use these rates, only after certification by its actuary and approval by CMS.' [CN-680000-FP122: 236] - 'This Contract shall be amended only as follows (unless specified elsewhere in this Contract): a. The parties cannot amend or alter the terms of this Contract without a written amendment and/or change order to this Contract.' [CN-680000-FP122: 286] | I11: MCO | J11: HIO | K11: PIHP | L11: PAHP | M11: NEMT PAHP | O11: PCCME | P11: EXISTING | Q11: =IF(OR(AND($C$2="Base contract",$C$3="No, section requirements must be reviewed",$AG11=FALSE, $AH11=FALSE),AND($C$2="Contract amendment",$C$3="No, section requirements must be reviewed",$AG11=FALSE,$AH11=FALSE)),"YNNN") | U11: =IF(OR($E$8="N/A",AND(E11="Yes",F11<>""),AND(E11="N/A",H11<>""),AND(E11="Met",F11<>""),AND(E11="Not met",G11<>""),AND(E11="Unsure",G11<>""),AND(E11="N/A"),AND(E11="No",G11<>""),AND(E11="No, submission is in draft",G11<>""),AND(R11=1),AND(Y11=TRUE)),1,0) | X11: =IF(OR(Y11=TRUE),TRUE,FALSE) | Y11: =IF(SUM(Z11:AE11)<1,TRUE,FALSE) | Z11: =IF($Z$2=I11,1,0) | AA11: =IF($AA$2=J11,1,0) | AB11: =IF($AB$2=K11,1,0) | AC11: =IF($AC$2=L11,1,0) | AD11: =IF($AD$2=M11,1,0) | AE11: =IF($AE$2=O11,1,0) | AM11: =IF(AND('Cover Sheet'!$B$19="Non-Risk",$R11=1),TRUE,FALSE) | AN11: =IF(AND($H$6="Medicaid",MID($A11,1,FIND(".",$A11,1)-1)="II"),TRUE,FALSE) | AU11: 1 | AV11: =IF(AU11=1,1,"") | BE11: 0
A12: I.A.1.03 | B12: 42 CFR 438.7(a) | C12: If the contract submission implements capitation rates or a change in the contract may impact 42 CFR 438.4, CMS has received a rate certification from the state. | D12: 2,3,5,6 | F12: Source: CN-680000-FP122: 236, 175 | Attachment - Core Contract Provisions 02012025: 175, 236 | H12: Recommendation: UNCLEAR Response: The retrieved text mentions capitation rates and the need for CMS approval, but it does not explicitly state that CMS has received a rate certification from the state when capitation rates are implemented or when a change in the contract may impact 42 CFR 438.4. The text states that 'The Agency may use, or may amend and use these rates, only after certification by its actuary and approval by CMS' [1][2], but it does not confirm that CMS has received a rate certification from the state under the specified conditions. | I12: MCO | J12: HIO | K12: PIHP | L12: PAHP | P12: EXISTING | Q12: =IF(OR(AND($C$2="Base contract",$C$3="No, section requirements must be reviewed",$AG12=FALSE, $AH12=FALSE),AND($C$2="Contract amendment",$C$3="No, section requirements must be reviewed",$AG12=FALSE,$AH12=FALSE)),"YNNN") | S12: 42556 | U12: =IF(OR($E$8="N/A",AND(E12="Yes",F12<>""),AND(E12="N/A",H12<>""),AND(E12="Met",F12<>""),AND(E12="Not met",G12<>""),AND(E12="Unsure",G12<>""),AND(E12="N/A"),AND(E12="No",G12<>""),AND(E12="No, submission is in draft",G12<>""),AND(R12=1),AND(Y12=TRUE)),1,0) | X12: =IF(OR(Y12=TRUE),TRUE,FALSE) | Y12: =IF(SUM(Z12:AE12)<1,TRUE,FALSE) | Z12: =IF($Z$2=I12,1,0) | AA12: =IF($AA$2=J12,1,0) | AB12: =IF($AB$2=K12,1,0) | AC12: =IF($AC$2=L12,1,0) | AD12: =IF($AD$2=M12,1,0) | AE12: =IF($AE$2=O12,1,0) | AM12: =IF(AND('Cover Sheet'!$B$19="Non-Risk",$R12=1),TRUE,FALSE) | AN12: =IF(AND($H$6="Medicaid",MID($A12,1,FIND(".",$A12,1)-1)="II"),TRUE,FALSE) | AU12: 1 | AV12: =IF(AU12=1,1,"") | BE12: 0
A13: I.A.1.04 | B13: 42 CFR 438.7(c)(3); 42 CFR 438.7(b)(6) | C13: If the state is increasing or decreasing previously certified rates without submitting a rate certification, the rate change must be within 1.5% per rate cell of the rates previously certified for the applicable rating period, and the change that accompanies this de minimis rate change must not be for a change in special contract provisions related to payment in 42 CFR 438.6 that is applied to the contract (e.g., state directed payment). | D13: 1,2,6,7,19 | F13: Source: Attachment - Core Contract Provisions 02012025: 176, 175 | CN-680000-FP122: 237, 236, 23, 236, 175, 417 | H13: Recommendation: UNCLEAR Response: The retrieved text does not provide explicit evidence that addresses the specific conditions outlined in the requirement. The text mentions adjustments to rates and the need for certification and approval, but it does not specify the 1.5% limit or the restriction on changes to special contract provisions related to payment in 42 CFR 438.6. | I13: MCO | J13: HIO | K13: PIHP | L13: PAHP | P13: EXISTING | Q13: =IF(OR(AND($C$2="Base contract",$C$3="No, section requirements must be reviewed",$AG13=FALSE, $AH13=FALSE),AND($C$2="Contract amendment",$C$3="No, section requirements must be reviewed",$AG13=FALSE,$AH13=FALSE)),"YNNN") | U13: =IF(OR($E$8="N/A",AND(E13="Yes",F13<>""),AND(E13="N/A",H13<>""),AND(E13="Met",F13<>""),AND(E13="Not met",G13<>""),AND(E13="Unsure",G13<>""),AND(E13="N/A"),AND(E13="No",G13<>""),AND(E13="No, submission is in draft",G13<>""),AND(R13=1),AND(Y13=TRUE),X13=TRUE),1,0) | X13: =IF(OR(Y13=TRUE,BF13=0),TRUE,FALSE) | Y13: =IF(SUM(Z13:AE13)<1,TRUE,FALSE) | Z13: =IF($Z$2=I13,1,0) | AA13: =IF($AA$2=J13,1,0) | AB13: =IF($AB$2=K13,1,0) | AC13: =IF($AC$2=L13,1,0) | AD13: =IF($AD$2=M13,1,0) | AE13: =IF($AE$2=O13,1,0) | AM13: =IF(AND('Cover Sheet'!$B$19="Non-Risk",$R13=1),TRUE,FALSE) | AN13: =IF(AND($H$6="Medicaid",MID($A13,1,FIND(".",$A13,1)-1)="II"),TRUE,FALSE) | AU13: 1 | AV13: =IF(AU13=1,1,"") | BE13: 0 | BF13: =IF(BF14=1,0,1)
A14: I.A.1.04 | B14: 42 CFR 438.7(c)(3); 42 CFR 438.7(b)(6) | C14: If the state is increasing or decreasing previously certified rates without submitting a rate certification, the rate change must be within 1.5% per rate cell of the rates previously certified for the applicable rating period, and the change that accompanies this de minimis rate change must not be for a change in special contract provisions related to payment in 42 CFR 438.6 or in lieu of services and settings (ILOSs) that is applied to the contract (e.g., state directed payment). | D14: 1,2,6,7,19 | F14: Source: Attachment - Core Contract Provisions 02012025: 176, 237, 236, 175 | CN-680000-FP122: 236, 175, 417, 23 | H14: Recommendation: UNCLEAR Response: The retrieved text does not provide explicit evidence that addresses the specific conditions outlined in the requirement. The text discusses adjustments to capitation rates, but it does not specify the percentage change allowed without a rate certification or the restrictions on changes to special contract provisions related to payment. Therefore, it is unclear whether the requirement is met. | I14: MCO | J14: HIO | K14: PIHP | L14: PAHP | P14: EXISTING | Q14: =IF(OR(AND($C$2="Base contract",$C$3="No, section requirements must be reviewed",$AG14=FALSE, $AH14=FALSE),AND($C$2="Contract amendment",$C$3="No, section requirements must be reviewed",$AG14=FALSE,$AH14=FALSE)),"YNNN") | S14: 45544 | U14: =IF(OR($E$8="N/A",AND(E14="Yes",F14<>""),AND(E14="N/A",H14<>""),AND(E14="Met",F14<>""),AND(E14="Not met",G14<>""),AND(E14="Unsure",G14<>""),AND(E14="N/A"),AND(E14="No",G14<>""),AND(E14="No, submission is in draft",G14<>""),AND(R14=1),AND(Y14=TRUE),X14=TRUE),1,0) | X14: =IF(OR(Y14=TRUE,BF14=0),TRUE,FALSE) | Y14: =IF(SUM(Z14:AE14)<1,TRUE,FALSE) | Z14: =IF($Z$2=I14,1,0) | AA14: =IF($AA$2=J14,1,0) | AB14: =IF($AB$2=K14,1,0) | AC14: =IF($AC$2=L14,1,0) | AD14: =IF($AD$2=M14,1,0) | AE14: =IF($AE$2=O14,1,0) | AM14: =IF(AND('Cover Sheet'!$B$19="Non-Risk",$R14=1),TRUE,FALSE) | AN14: =IF(AND($H$6="Medicaid",MID($A14,1,FIND(".",$A14,1)-1)="II"),TRUE,FALSE) | AU14: 1 | AV14: =IF(AU14=1,1,"") | BE14: 0 | BF14: =IF('Cover Sheet'!$B$25>=S14,1,0)
A15: I.A.1.05 | B15: 42 CFR 438.4(c)(2)(iii) | C15: If the state is increasing or decreasing rates within a previously certified rate range without submitting a rate certification, the rate change must be within 1% per rate cell within the rate range previously certified for the applicable rating period in accordance with the requirements in 42 CFR 438.4(c)(2)(iii). | D15: 8,9,10,19 | F15: Source: Attachment - Core Contract Provisions 02012025: 176, 237 | CN-680000-FP122: 236, 237 | H15: Recommendation: UNCLEAR Response: The retrieved text does not provide explicit evidence regarding the specific requirement that rate changes within a previously certified rate range must be within 1% per rate cell without submitting a new rate certification. The text mentions adjustments to capitation rates and the need for proper execution of amendments, but it does not specify the percentage limit for rate changes or the conditions under which these changes can be made without a new certification. Therefore, it is unclear whether the requirement is met based on the provided context. | I15: MCO | J15: HIO | K15: PIHP | L15: PAHP | P15: NEW | Q15: =IF(OR(AND($C$2="Base contract",$C$3="No, section requirements must be reviewed",$AG15=FALSE, $AH15=FALSE),AND($C$2="Contract amendment",$C$3="No, section requirements must be reviewed",$AG15=FALSE,$AH15=FALSE)),"YNNN") | R15: =IF('Cover Sheet'!$B$19="Non-Risk",1) | S15: 44378 | T15: RP | U15: =IF(OR($E$8="N/A",AND(E15="Yes",F15<>""),AND(E15="N/A",H15<>""),AND(E15="Met",F15<>""),AND(E15="Not met",G15<>""),AND(E15="Unsure",G15<>""),AND(E15="N/A"),AND(E15="No",G15<>""),AND(E15="No, submission is in draft",G15<>""),AND(R15=1),AND(Y15=TRUE)),1,0) | V15: =IF(AND($V$2="Non-risk",T15="RP"),"DATE",T15) | X15: =IF(OR(Y15=TRUE),TRUE,FALSE) | Y15: =IF(SUM(Z15:AE15)<1,TRUE,FALSE) | Z15: =IF($Z$2=I15,1,0) | AA15: =IF($AA$2=J15,1,0) | AB15: =IF($AB$2=K15,1,0) | AC15: =IF($AC$2=L15,1,0) | AD15: =IF($AD$2=M15,1,0) | AE15: =IF($AE$2=O15,1,0) | AI15: =IF(OR($AH$2=TRUE,AND('Cover Sheet'!$B$19="Risk")),TRUE,"") | AJ15: =IF(OR(AK15=TRUE,AL15=TRUE,AM15=TRUE,AN15=TRUE),TRUE,"") | AK15: =IF(V15="DATE",IF($AH$2=FALSE,IF(S15>$AI$2,TRUE,"ReqEffectiveEarlierThanContractDate"),"Dates Missing"),"Not DATE") | AL15: =IF(V15="RP",IF($AH$2=FALSE,IF(S15>$AJ$2,TRUE,"ReqEffectiveEarlierThanRatePeriodStartDate"),"Dates Missing"),"Not RP") | AM15: =IF(AND('Cover Sheet'!$B$19="Non-Risk",$R15=1),TRUE,FALSE) | AN15: =IF(AND($H$6="Medicaid",MID($A15,1,FIND(".",$A15,1)-1)="II"),TRUE,FALSE) | AU15: 1 | AV15: =IF(AU15=1,1,"") | BD15: RP | BE15: 0
A16: I.A.1.06 | B16: 42 CFR 7(c)(4) | C16: If the state is making any changes to the capitation rate per rate cell for state directed payments not already described in the rate certification, regardless of the size of the change in the capitation rate per rate cell, the state has submitted a revised rate certification. | D16: 7 | F16: Source: Attachment - Core Contract Provisions 02012025: 175 | CN-680000-FP122: 236 | H16: Recommendation: UNCLEAR Response: The retrieved text does not provide explicit evidence that the state has submitted a revised rate certification when making changes to the capitation rate per rate cell for state directed payments not already described in the rate certification. The text mentions adjustments to capitation rates and the need for amendments to the contract, but it does not specifically address the requirement of submitting a revised rate certification for such changes. Relevant excerpts: - 'Funds previously paid shall be adjusted when capitation rate calculations are determined to have been in error, or when capitation rate payments have been made for enrollees who are determined not to have been eligible for Managed Care Plan membership during the period for which the capitation rate payments were made. In such events, the Managed Care Plan and any subcontractor shall report to the State within sixty (60) days when' [Attachment - Core Contract Provisions 02012025: 175] - 'The state must adjust capitation rates to remove costs that are specific to any program or activity that is no longer authorized by law.' [CN-680000-FP122: 236] | I16: MCO | J16: HIO | K16: PIHP | L16: PAHP | U16: =IF(OR($E$8="N/A",AND(E16="Yes",F16<>""),AND(E16="N/A",H16<>""),AND(E16="Met",F16<>""),AND(E16="Not met",G16<>""),AND(E16="Unsure",G16<>""),AND(E16="N/A"),AND(E16="No",G16<>""),AND(E16="No, submission is in draft",G16<>""),AND(R16=1),AND(Y16=TRUE)),1,0) | X16: =IF(OR(Y16=TRUE,BF16=0),TRUE,FALSE) | Y16: =IF(SUM(Z16:AE16)<1,TRUE,FALSE) | Z16: =IF($Z$2=I16,1,0) | AA16: =IF($AA$2=J16,1,0) | AB16: =IF($AB$2=K16,1,0) | AC16: =IF($AC$2=L16,1,0) | AD16: =IF($AD$2=M16,1,0) | AE16: =IF($AE$2=O16,1,0) | BF16: =IF(BF17=1,0,1)
A17: I.A.1.06 | B17: 42 CFR 7(c)(4) | C17: If the state is making any changes to the capitation rate per rate cell for state directed payments or ILOSs not already described in the rate certification, regardless of the size of the change in the capitation rate per rate cell, the state has submitted a revised rate certification. | D17: 7 | F17: Source: Attachment - Core Contract Provisions 02012025: 175 | CN-680000-FP122: 236 | H17: Recommendation: UNCLEAR Response: The retrieved text does not provide explicit evidence that the state has submitted a revised rate certification when making changes to the capitation rate per rate cell for state directed payments or ILOSs not already described in the rate certification. The text mentions adjustments to capitation rates and the need for amendments to the contract, but it does not specifically state that a revised rate certification is required for such changes. Evidence: - 'The Managed Care Plan and the Agency acknowledge that adjustments to funds previously paid, and to funds yet to be paid, may be required.' [Attachment - Core Contract Provisions 02012025: 175] - 'The state must adjust capitation rates to remove costs that are specific to any program or activity that is no longer authorized by law.' [CN-680000-FP122: 236] There is no explicit mention of a revised rate certification being submitted for changes to the capitation rate per rate cell. | I17: MCO | J17: HIO | K17: PIHP | L17: PAHP | S17: 45482 | U17: =IF(OR($E$8="N/A",AND(E17="Yes",F17<>""),AND(E17="N/A",H17<>""),AND(E17="Met",F17<>""),AND(E17="Not met",G17<>""),AND(E17="Unsure",G17<>""),AND(E17="N/A"),AND(E17="No",G17<>""),AND(E17="No, submission is in draft",G17<>""),AND(R17=1),AND(X17=TRUE),AND(Y17=TRUE)),1,0) | X17: =IF(OR(Y17=TRUE,BF17=0),TRUE,FALSE) | Y17: =IF(SUM(Z17:AE17)<1,TRUE,FALSE) | Z17: =IF($Z$2=I17,1,0) | AA17: =IF($AA$2=J17,1,0) | AB17: =IF($AB$2=K17,1,0) | AC17: =IF($AC$2=L17,1,0) | AD17: =IF($AD$2=M17,1,0) | AE17: =IF($AE$2=O17,1,0) | BF17: =IF('Cover Sheet'!$B$25>=S17,1,0)
A18: I.A.1.07 | B18: 42 CFR 438.74(a) | C18: If the contract submission implements capitation rates for the state’s annual rating period, DMCO received the state's summary description of medical loss ratio (MLR) reports received from the MCPs under contract with the state. | D18: 2,3,4,11 | F18: Source: CN-680000-FP122: 35, 10, 448 | Attachment - Core Contract Provisions 02012025: 247, 175 | H18: Recommendation: MET Response: The contract text explicitly mentions capitation rates and the annual rating period. For example, it states: 'The capitation rate payment shall be in accordance with **Attachment II and its Exhibits.** The capitation rates are contained in **Exhibit I-C,** Managed Care Plan Rates - Not for Use Unless Approved by CMS, of this Attachment.' (CN-680000-FP122: 35, 10). Additionally, the contract requires the Managed Care Plan to maintain an annual medical loss ratio (MLR) of a minimum of eighty-five percent (85%) (CN-680000-FP122: 448). This indicates that the contract submission implements capitation rates for the state’s annual rating period and that DMCO received the state's summary description of MLR reports. | I18: MCO | J18: HIO | K18: PIHP | L18: PAHP | P18: EXISTING | Q18: =IF(OR(AND($C$2="Base contract",$C$3="No, section requirements must be reviewed",$AG18=FALSE, $AH18=FALSE),AND($C$2="Contract amendment",$C$3="No, section requirements must be reviewed",$AG18=FALSE,$AH18=FALSE)),"YNNN") | R18: =IF('Cover Sheet'!$B$19="Non-Risk",1) | U18: =IF(OR($E$8="N/A",AND(E18="Yes",F18<>""),AND(E18="N/A",H18<>""),AND(E18="Met",F18<>""),AND(E18="Not met",G18<>""),AND(E18="Unsure",G18<>""),AND(E18="N/A"),AND(E18="No",G18<>""),AND(E18="No, submission is in draft",G18<>""),AND(R18=1),AND(Y18=TRUE),X18=TRUE),1,0) | X18: =IF(OR(Y18=TRUE,BF18=0),TRUE,FALSE) | Y18: =IF(SUM(Z18:AE18)<1,TRUE,FALSE) | Z18: =IF($Z$2=I18,1,0) | AA18: =IF($AA$2=J18,1,0) | AB18: =IF($AB$2=K18,1,0) | AC18: =IF($AC$2=L18,1,0) | AD18: =IF($AD$2=M18,1,0) | AE18: =IF($AE$2=O18,1,0) | AM18: =IF(AND('Cover Sheet'!$B$19="Non-Risk",$R18=1),TRUE,FALSE) | AN18: =IF(AND($H$6="Medicaid",MID($A18,1,FIND(".",$A18,1)-1)="II"),TRUE,FALSE) | AV18: =IF(AU18=1,1,"") | BE18: 0 | BF18: =IF(BF19=1,0,1)
A19: I.A.1.07 | B19: 42 CFR 438.74(a) | C19: If the contract submission implements capitation rates for the state’s annual rating period, DMCO received the state's summary description of medical loss ratio (MLR) reports received from the MCPs under contract with the state. The summary description must be provided for each MCP under contract with the state. | D19: 2,3,4,11 | F19: Source: Attachment - Core Contract Provisions 02012025: 175, 242 | CN-680000-FP122: 448 | H19: Recommendation: UNCLEAR Response: The retrieved text mentions capitation rates and MLR reports, but it does not explicitly state that DMCO received the state's summary description of MLR reports for each MCP under contract with the state when capitation rates are implemented for the state’s annual rating period. The text refers to general reporting requirements and MLR maintenance but lacks specific details about the provision of summary descriptions to DMCO. Evidence: - "Unless otherwise specified in this Contract, the Managed Care Plan shall accept the capitation payment received each month as payment in full by the Agency for all services provided to enrollees covered under this Contract..." [Attachment - Core Contract Provisions 02012025: 175] - "The Managed Care Plan shall comply with reports required by the Agency as specified in the Managed Care Plan Submissions Summary..." [Attachment - Core Contract Provisions 02012025: 242] - "The Managed Care Plan shall maintain an annual (January 1 - December 31) medical loss ratio (MLR) of a minimum of eighty-five percent (85%) for the fir" [CN-680000-FP122: 448] | I19: MCO | J19: HIO | K19: PIHP | L19: PAHP | P19: EXISTING | Q19: =IF(OR(AND($C$2="Base contract",$C$3="No, section requirements must be reviewed",$AG19=FALSE, $AH19=FALSE),AND($C$2="Contract amendment",$C$3="No, section requirements must be reviewed",$AG19=FALSE,$AH19=FALSE)),"YNNN") | R19: =IF('Cover Sheet'!$B$19="Non-Risk",1) | S19: 45482 | U19: =IF(OR($E$8="N/A",AND(E19="Yes",F19<>""),AND(E19="N/A",H19<>""),AND(E19="Met",F19<>""),AND(E19="Not met",G19<>""),AND(E19="Unsure",G19<>""),AND(E19="N/A"),AND(E19="No",G19<>""),AND(E19="No, submission is in draft",G19<>""),AND(R19=1),AND(Y19=TRUE),X19=TRUE),1,0) | X19: =IF(OR(Y19=TRUE,BF19=0),TRUE,FALSE) | Y19: =IF(SUM(Z19:AE19)<1,TRUE,FALSE) | Z19: =IF($Z$2=I19,1,0) | AA19: =IF($AA$2=J19,1,0) | AB19: =IF($AB$2=K19,1,0) | AC19: =IF($AC$2=L19,1,0) | AD19: =IF($AD$2=M19,1,0) | AE19: =IF($AE$2=O19,1,0) | AM19: =IF(AND('Cover Sheet'!$B$19="Non-Risk",$R19=1),TRUE,FALSE) | AN19: =IF(AND($H$6="Medicaid",MID($A19,1,FIND(".",$A19,1)-1)="II"),TRUE,FALSE) | AV19: =IF(AU19=1,1,"") | BE19: 0 | BF19: =IF('Cover Sheet'!$B$25>=S19,1,0)
A20: I.A.1.08 | B20: 42 CFR 438.1(b) | C20: The contract submission complies with the federal authority(ies) approved by CMS. For example, if the contractor delivers services for a program authorized under section 1915(b)/1915(c) concurrent authority, the contract is in compliance with the approved section 1915(b)/1915(c) waivers. If the contract action includes a new benefit, the state has submitted a state plan amendment (SPA) or waiver amendment, requesting authority to cover the benefit. | D20: 12 | F20: Source: CN-680000-FP122: 278, 217, 230, 290, 199, 3, 138, 463 | Attachment - Core Contract Provisions 02012025: 217, 230, 138 | H20: Recommendation: UNCLEAR Response: The retrieved text mentions compliance with federal CMS waivers and applicable federal requirements, but it does not explicitly state that the contract complies with specific federal authorities such as section 1915(b)/1915(c) waivers or provide evidence of a state plan amendment (SPA) or waiver amendment for new benefits. Therefore, it is unclear whether the requirement is met based on the provided context. | I20: MCO | J20: HIO | K20: PIHP | L20: PAHP | M20: NEMT PAHP | O20: PCCME | P20: EXISTING | Q20: =IF(OR(AND($C$2="Base contract",$C$3="No, section requirements must be reviewed",$AG20=FALSE, $AH20=FALSE),AND($C$2="Contract amendment",$C$3="No, section requirements must be reviewed",$AG20=FALSE,$AH20=FALSE)),"YNNN") | U20: =IF(OR($E$8="N/A",AND(E20="Yes",F20<>""),AND(E20="N/A",H20<>""),AND(E20="Met",F20<>""),AND(E20="Not met",G20<>""),AND(E20="Unsure",G20<>""),AND(E20="N/A"),AND(E20="No",G20<>""),AND(E20="No, submission is in draft",G20<>""),AND(R20=1),AND(Y20=TRUE)),1,0) | X20: =IF(OR(Y20=TRUE),TRUE,FALSE) | Y20: =IF(SUM(Z20:AE20)<1,TRUE,FALSE) | Z20: =IF($Z$2=I20,1,0) | AA20: =IF($AA$2=J20,1,0) | AB20: =IF($AB$2=K20,1,0) | AC20: =IF($AC$2=L20,1,0) | AD20: =IF($AD$2=M20,1,0) | AE20: =IF($AE$2=O20,1,0) | AM20: =IF(AND('Cover Sheet'!$B$19="Non-Risk",$R20=1),TRUE,FALSE) | AN20: =IF(AND($H$6="Medicaid",MID($A20,1,FIND(".",$A20,1)-1)="II"),TRUE,FALSE) | AU20: 1 | AV20: =IF(AU20=1,1,"") | BE20: 0
